<?xml version="1.0" encoding="utf-8"?>
<robot
  name="scorbot">
  <link name="world">
  </link>
  <link
    name="base_link">
    <inertial>
      <origin
        xyz="6.9389E-18 0.65 0.041357"
        rpy="0 0 0" />
      <mass
        value="24.144" />
      <inertia
        ixx="3.4129"
        ixy="-2.7635E-18"
        ixz="1.5076E-18"
        iyy="0.028252"
        iyz="3.1049E-17"
        izz="3.416" />
    </inertial>
    <visual>
      <origin
        xyz="0 0 0"
        rpy="0 0 0" />
      <geometry>
        <mesh
          filename="package://scorbot/meshes/slide_base_link.STL" />
      </geometry>
      <material
        name="">
        <color
          rgba="0.89804 0.91765 0.92941 1" />
      </material>
    </visual>
    <collision>
      <origin
        xyz="0 0 0"
        rpy="0 0 0" />
      <geometry>
        <mesh
          filename="package://scorbot/meshes/slide_base_link.STL" />
      </geometry>
    </collision>
  </link>
  <joint name="world_joint" type="fixed">
    <parent link="world" />
    <child link="base_link" />
  </joint>
  <link
    name="slide_base_link">
    <inertial>
      <origin
        xyz="-0.012271 0.012815 0"
        rpy="0 0 0" />
      <mass
        value="5.7681" />
      <inertia
        ixx="0.071205"
        ixy="-0.0043325"
        ixz="6.0569E-17"
        iyy="0.070116"
        iyz="2.4488E-17"
        izz="0.08178" />
    </inertial>
    <visual>
      <origin
        xyz="0 0 0"
        rpy="0 0 0" />
      <geometry>
        <mesh
          filename="package://scorbot/meshes/base_link.STL" />
      </geometry>
      <material
        name="">
        <color
          rgba="0.89804 0.91765 0.92941 1" />
      </material>
    </visual>
    <collision>
      <origin
        xyz="0 0 0"
        rpy="0 0 0" />
      <geometry>
        <mesh
          filename="package://scorbot/meshes/base_link.STL" />
      </geometry>
    </collision>
  </link>
  <joint
    name="slide_base_joint"
    type="prismatic">
    <origin
      xyz="0 0.17 0.096"
      rpy="1.5708 0 3.1416" />
    <parent
      link="base_link" />
    <child
      link="slide_base_link" />
    <axis
      xyz="0 0 1" />
    <limit
      lower="0"
      upper="0.9"
      effort="0"
      velocity="0" />
  </joint>
  <link
    name="body_link">
    <inertial>
      <origin
        xyz="-0.0024124 0.0019378 -0.070016"
        rpy="0 0 0" />
      <mass
        value="4.1847" />
      <inertia
        ixx="0.029582"
        ixy="0.00098745"
        ixz="0.0042693"
        iyy="0.027732"
        iyz="-0.00082029"
        izz="0.03323" />
    </inertial>
    <visual>
      <origin
        xyz="0 0 0"
        rpy="0 0 0" />
      <geometry>
        <mesh
          filename="package://scorbot/meshes/body_link.STL" />
      </geometry>
      <material
        name="">
        <color
          rgba="0.89804 0.91765 0.92941 1" />
      </material>
    </visual>
    <collision>
      <origin
        xyz="0 0 0"
        rpy="0 0 0" />
      <geometry>
        <mesh
          filename="package://scorbot/meshes/body_link.STL" />
      </geometry>
    </collision>
  </link>
  <joint
    name="body_joint"
    type="continuous">
    <origin
      xyz="0 0.354 0"
      rpy="-1.5708 -1.5708 0" />
    <parent
      link="slide_base_link" />
    <child
      link="body_link" />
    <axis
      xyz="0 0 1" />
    <dynamics damping="0.7" />
  </joint>
  <link
    name="shoulder_link">
    <inertial>
      <origin
        xyz="0.10172 0.0057759 -4.0246E-16"
        rpy="0 0 0" />
      <mass
        value="2.1816" />
      <inertia
        ixx="0.011823"
        ixy="-3.4979E-05"
        ixz="1.0635E-17"
        iyy="0.028073"
        iyz="1.3636E-17"
        izz="0.017919" />
    </inertial>
    <visual>
      <origin
        xyz="0 0 0"
        rpy="0 0 0" />
      <geometry>
        <mesh
          filename="package://scorbot/meshes/shoulder_link.STL" />
      </geometry>
      <material
        name="">
        <color
          rgba="0.64706 0.61961 0.58824 1" />
      </material>
    </visual>
    <collision>
      <origin
        xyz="0 0 0"
        rpy="0 0 0" />
      <geometry>
        <mesh
          filename="package://scorbot/meshes/shoulder_link.STL" />
      </geometry>
    </collision>
  </link>
  <joint
    name="shoulder_joint"
    type="continuous">
    <origin
      xyz="0.025 0 0"
      rpy="1.5708 0 0" />
    <parent
      link="body_link" />
    <child
      link="shoulder_link" />
    <axis
      xyz="0 0 1" />
    <dynamics damping="0.7" />
  </joint>
  <link
    name="elbow_link">
    <inertial>
      <origin
        xyz="0.1333 0.0044924 1.249E-16"
        rpy="0 0 0" />
      <mass
        value="1.3299" />
      <inertia
        ixx="0.0056088"
        ixy="0.00042004"
        ixz="-1.9107E-17"
        iyy="0.014028"
        iyz="5.212E-20"
        izz="0.009294" />
    </inertial>
    <visual>
      <origin
        xyz="0 0 0"
        rpy="0 0 0" />
      <geometry>
        <mesh
          filename="package://scorbot/meshes/elbow_link.STL" />
      </geometry>
      <material
        name="">
        <color
          rgba="0.64706 0.61961 0.58824 1" />
      </material>
    </visual>
    <collision>
      <origin
        xyz="0 0 0"
        rpy="0 0 0" />
      <geometry>
        <mesh
          filename="package://scorbot/meshes/elbow_link.STL" />
      </geometry>
    </collision>
  </link>
  <joint
    name="elbow_joint"
    type="continuous">
    <origin
      xyz="0.22 0 0"
      rpy="0 0 0" />
    <parent
      link="shoulder_link" />
    <child
      link="elbow_link" />
    <axis
      xyz="0 0 1" />
    <dynamics damping="0.7" />
  </joint>
  <link
    name="wrist_link">
    <inertial>
      <origin
        xyz="5.5511E-17 0.0016897 2.7756E-17"
        rpy="0 0 0" />
      <mass
        value="0.11142" />
      <inertia
        ixx="0.00015149"
        ixy="-3.4232E-21"
        ixz="4.5808E-20"
        iyy="0.00012081"
        iyz="3.5338E-20"
        izz="6.0971E-05" />
    </inertial>
    <visual>
      <origin
        xyz="0 0 0"
        rpy="0 0 0" />
      <geometry>
        <mesh
          filename="package://scorbot/meshes/wrist_link.STL" />
      </geometry>
      <material
        name="">
        <color
          rgba="0.64314 0.61569 0.6 1" />
      </material>
    </visual>
    <collision>
      <origin
        xyz="0 0 0"
        rpy="0 0 0" />
      <geometry>
        <mesh
          filename="package://scorbot/meshes/wrist_link.STL" />
      </geometry>
    </collision>
  </link>
  <joint
    name="wrist_joint"
    type="continuous">
    <origin
      xyz="0.22 0 0"
      rpy="0 0 1.5708" />
    <parent
      link="elbow_link" />
    <child
      link="wrist_link" />
    <axis
      xyz="0 0 1" />
    <dynamics damping="0.7" />
  </joint>
  <link
    name="roll_wrist_link">
    <inertial>
      <origin
        xyz="-0.00011221 -0.0098074 0.096196"
        rpy="0 0 0" />
      <mass
        value="0.3891" />
      <inertia
        ixx="0.0013614"
        ixy="0.0"
        ixz="0.0"
        iyy="0.00015489"
        iyz="0.0"
        izz="0.0010547" />
    </inertial>
    <visual>
      <origin
        xyz="0 0 0"
        rpy="0 0 0" />
      <geometry>
        <mesh
          filename="package://scorbot/meshes/roll_wrist_link.STL" />
      </geometry>
      <material
        name="">
        <color
          rgba="0.75294 0.75294 0.75294 0.5" />
      </material>
    </visual>
    <collision>
      <origin
        xyz="0 0 0"
        rpy="0 0 0" />
      <geometry>
        <mesh
          filename="package://scorbot/meshes/roll_wrist_link.STL" />
      </geometry>
    </collision>
  </link>
  <joint
    name="roll_wrist_joint"
    type="continuous">
    <origin
      xyz="0 0 0"
      rpy="1.5708 0 0" />
    <parent
      link="wrist_link" />
    <child
      link="roll_wrist_link" />
    <axis
      xyz="0 0 1" />
    <dynamics damping="0.7" />
  </joint>
  <link
    name="extruder_link">
    <inertial>
      <origin
        xyz="0.0001115 0 -0.004905"
        rpy="0 0 0" />
      <mass
        value="0.00058199" />
      <inertia
        ixx="0.001"
        ixy="0.0"
        ixz="0.0"
        iyy="0.01"
        iyz="0.0"
        izz="0.01" />
    </inertial>
    <visual>
      <origin
        xyz="0 0 0"
        rpy="0 0 0" />
      <geometry>
        <mesh
          filename="package://scorbot/meshes/extruder_link.STL" />
      </geometry>
      <material
        name="">
        <color
          rgba="1 0 0 1" />
      </material>
    </visual>
    <collision>
      <origin
        xyz="0 0 0"
        rpy="0 0 0" />
      <geometry>
        <mesh
          filename="package://scorbot/meshes/extruder_link.STL" />
      </geometry>
    </collision>
  </link>
  <joint
    name="extruder_screw_joint"
    type="continuous">
    <origin
      xyz="0 -0.011037 0.126"
      rpy="-1.5708 3.1416 0" />
    <parent
      link="roll_wrist_link" />
    <child
      link="extruder_link" />
    <axis
      xyz="0 0 1" />
    <dynamics damping="0.7" />
  </joint>

  <link name="hotend_link">
  </link>
  <joint name="hotend_joint" type="fixed">
    <origin xyz="-0.049 -0.0137 0.132"
            rpy="0 -1.5708 0" />
    <parent link="roll_wrist_link" />
    <child link="hotend_link"/>
  </joint>

  <ros2_control name="GazeboSimSystem" type="system">

    <hardware>
      <plugin>gazebo_ros2_control/GazeboSystem</plugin>
    </hardware>

    <joint name="slide_base_joint">
      <command_interface name="position" />
      <state_interface name="position">
        <param name="initial_value">0.0</param>
      </state_interface>
      <state_interface name="velocity" />
    </joint>

    <joint name="body_joint">
      <command_interface name="position" />
      <state_interface name="position">
        <param name="initial_value">0.0</param>
      </state_interface>
      <state_interface name="velocity" />
    </joint>

    <joint name="shoulder_joint">
      <command_interface name="position" />
      <state_interface name="position">
        <param name="initial_value">0.0</param>
      </state_interface>
      <state_interface name="velocity" />
    </joint>

    <joint name="elbow_joint">
      <command_interface name="position" />
      <state_interface name="position">
        <param name="initial_value">0.0</param>
      </state_interface>
      <state_interface name="velocity" />
    </joint>

    <joint name="wrist_joint">
      <command_interface name="position" />
      <state_interface name="position">
        <param name="initial_value">0.0</param>
      </state_interface>
      <state_interface name="velocity" />
    </joint>

    <joint name="roll_wrist_joint">
      <command_interface name="position" />
      <state_interface name="position">
        <param name="initial_value">0.0</param>
      </state_interface>
      <state_interface name="velocity" />
    </joint>

    <joint name="extruder_screw_joint">
      <command_interface name="position" />
      <state_interface name="position">
        <param name="initial_value">0.0</param>
      </state_interface>
      <state_interface name="velocity" />
    </joint>

  </ros2_control>
  <gazebo>
    <plugin filename="libgazebo_ros2_control.so" name="gazebo_ros2_control">
        <parameters>/home/luis/tesis_ws/src/scorbot/config/scorbot_er_v_controllers.yaml</parameters>
    </plugin>
</gazebo>

</robot>
