<?xml version="1.0" encoding="utf-8"?>
<!-- This URDF was automatically created by SolidWorks to URDF Exporter! Originally created by Stephen Brawner (brawner@gmail.com) 
     Commit Version: 1.6.0-4-g7f85cfe  Build Version: 1.6.7995.38578
     For more information, please see http://wiki.ros.org/sw_urdf_exporter -->
<robot
  name="scorbot-er-v-plus">
  <link name="world">
  </link>
  <link name="base_link">
    <inertial>
      <origin 
        xyz="0 0.65 0.04" rpy="0 0 0" /> 
      <mass value="54.14" /> 
      <inertia 
        ixx="13.66" ixy="0" ixz="0" 
        iyy="0.07" iyz="0.65" 
        izz="13.62" /> 
    </inertial>
    <visual>
      <origin
        xyz="0 0 0"
        rpy="0 0 0" />
      <geometry>
        <mesh
          filename="package://scorbot_er_v/meshes/slide_base_link.STL" />
      </geometry>
      <material
        name="">
        <color
          rgba="0.63921 0.63921 0.63921 1" />
      </material>
    </visual>
    <collision>
      <origin
        xyz="0 0 0"
        rpy="0 0 0" />
      <geometry>
        <mesh
          filename="package://scorbot_er_v/meshes/slide_base_link.STL" />
      </geometry>
    </collision>
  </link>
  <joint name="world_link" type="fixed">
    <parent link="world"/>
    <child link="base_link"/>
  </joint>
  <link name="slide_base_link">
    <inertial>
      <origin 
        xyz="-0.01 0.01 0" rpy="0 0 0" /> 
      <mass value="5.77" /> 
      <inertia  
        ixx="0.07" ixy="0" ixz="0" 
        iyy="0.07" iyz="0" 
        izz="0.08" /> 
    </inertial>
    <visual>
      <origin xyz="0 0 0" rpy="0 0 0" />
      <geometry>
        <mesh
          filename="package://scorbot_er_v/meshes/base_link.STL" />
      </geometry>
      <material
        name="">
        <color
          rgba="0.2666 0.2666 0.2666 1" />
      </material>
    </visual>
    <collision>
      <origin
        xyz="0 0 0"
        rpy="0 0 0" />
      <geometry>
        <mesh
          filename="package://scorbot_er_v/meshes/base_link.STL" />
      </geometry>
    </collision>
  </link>
  <joint name="slide_base_joint"
    type="prismatic">
    <origin
      xyz="0 0.17 0.096"
      rpy="1.570796327 0 3.141592654" />
    <parent link="base_link" />
    <child link="slide_base_link" />
    <axis xyz="0 0 1" />
    <limit
      lower="0"
      upper="0.950"
      effort="0"
      velocity="0" />
  </joint>
  <link name="body_link">
    <inertial>
      <origin 
        xyz="0 0 -0.07" rpy="0 0 0" /> 
      <mass value="4.26" /> 
      <inertia 
        ixx="0.05" ixy="0" ixz="0" 
        iyy="0.05" iyz="0" 
        izz="0.03" /> 
    </inertial>
    <visual>
      <origin
        xyz="0 0 0"
        rpy="0 0 0" />
      <geometry>
        <mesh
          filename="package://scorbot_er_v/meshes/body_link.STL" />
      </geometry>
      <material
        name="">
        <color
          rgba="0.63921 0.63921 0.63921 1" />
      </material>
    </visual>
    <collision>
      <origin
        xyz="0 0 0"
        rpy="0 0 0" />
      <geometry>
        <mesh
          filename="package://scorbot_er_v/meshes/body_link.STL" />
      </geometry>
    </collision>
  </link>
  <joint name="body_joint"
    type="continuous">
    <origin
      xyz="0 0.354 0"
      rpy="-1.570796327 -1.570796327 0" />
    <parent
      link="slide_base_link" />
    <child
      link="body_link" />
    <axis
      xyz="0 0 1" />
    <dynamics damping="0.7"/>
  </joint>
  <link name="shoulder_link">
    <inertial>
      <origin 
        xyz="0.10 0.01 0" rpy="0 0 0" /> 
      <mass value="2.16" /> 
      <inertia 
        ixx="0.01" ixy="0" ixz="0" 
        iyy="0.05" iyz="0" 
        izz="0.04" /> 
    </inertial>
    <visual>
      <origin
        xyz="0 0 0"
        rpy="0 0 0" />
      <geometry>
        <mesh
          filename="package://scorbot_er_v/meshes/shoulder_link.STL" />
      </geometry>
      <material
        name="">
        <color
          rgba="0.752941176470588 0.752941176470588 0.752941176470588 1" />
      </material>
    </visual>
    <collision>
      <origin
        xyz="0 0 0"
        rpy="0 0 0" />
      <geometry>
        <mesh
          filename="package://scorbot_er_v/meshes/shoulder_link.STL" />
      </geometry>
    </collision>
  </link>
  <joint name="shoulder_joint"
    type="continuous">
    <origin
      xyz="0.025 0 0"
      rpy="1.570796327 0 0" />
    <parent
      link="body_link" />
    <child
      link="shoulder_link" />
    <axis
      xyz="0 0 1" />
    <dynamics damping="0.7"/>
  </joint>
  <link name="elbow_link">
    <inertial>
      <origin 
        xyz="0.13 0 0" rpy="0 0 0" /> 
      <mass value="1.33" /> 
      <inertia 
        ixx="0.01" ixy="0" ixz="0" 
        iyy="0.04" iyz="0" 
        izz="0.03" /> 
    </inertial>
    <visual>
      <origin
        xyz="0 0 0"
        rpy="0 0 0" />
      <geometry>
        <mesh
          filename="package://scorbot_er_v/meshes/elbow_link.STL" />
      </geometry>
      <material
        name="">
        <color
          rgba="0.752941176470588 0.752941176470588 0.752941176470588 1" />
      </material>
    </visual>
    <collision>
      <origin
        xyz="0 0 0"
        rpy="0 0 0" />
      <geometry>
        <mesh
          filename="package://scorbot_er_v/meshes/elbow_link.STL" />
      </geometry>
    </collision>
  </link>
  <joint name="elbow_joint"
    type="continuous">
    <origin
      xyz="0.22 0 0"
      rpy="0 0 0" />
    <parent
      link="shoulder_link" />
    <child
      link="elbow_link" />
    <axis
      xyz="0 0 1" />
    <dynamics damping="0.7"/>
  </joint>
  <link name="wrist_link">
    <inertial>
      <origin 
        xyz="0 0 0" 
        rpy="0 0 0" />
      <mass value="0.11" />
      <inertia
        ixx="0.0001"
        ixy="0.000"
        ixz="0.000"
        iyy="0.0001"
        iyz="0.000"
        izz="0.0001" />
    </inertial>
    <visual>
      <origin
        xyz="0 0 0"
        rpy="0 0 0" />
      <geometry>
        <mesh
          filename="package://scorbot_er_v/meshes/wrist_link.STL" />
      </geometry>
      <material
        name="">
        <color
          rgba="0.752941176470588 0.752941176470588 0.752941176470588 1" />
      </material>
    </visual>
    <collision>
      <origin
        xyz="0 0 0"
        rpy="0 0 0" />
      <geometry>
        <mesh
          filename="package://scorbot_er_v/meshes/wrist_link.STL" />
      </geometry>
    </collision>
  </link>
  <joint name="wrist_joint"
    type="continuous">
    <origin
      xyz="0.22 0 0"
      rpy="0 0 1.5707963267949" />
    <parent
      link="elbow_link" />
    <child
      link="wrist_link" />
    <axis
      xyz="0 0 1" />
    <dynamics damping="0.7"/>
  </joint>
  <link name="roll_wrist_link">
    <inertial>
      <origin 
        xyz="0 0 0.069" 
        rpy="0 0 0" />
      <mass value="0.208" />
      <inertia
        ixx="0.001"
        ixy="0.000"
        ixz="0.000"
        iyy="0.001"
        iyz="0.000"
        izz="0.000" />
    </inertial>
    <visual>
      <origin
        xyz="0 0 0.0955"
        rpy="0 0 0" />
      <geometry>
        <mesh
          filename="package://scorbot_er_v/meshes/roll_wrist_link.STL" />
      </geometry>
      <material
        name="">
        <color
          rgba="0.898039215686275 0.917647058823529 0.929411764705882 1" />
      </material>
    </visual>
    <collision>
      <origin
        xyz="0 0 0.0955"
        rpy="0 0 0" />
      <geometry>
        <mesh
          filename="package://scorbot_er_v/meshes/roll_wrist_link.STL" />
      </geometry>
    </collision>
  </link>
  <joint name="roll_wrist_joint"
    type="continuous">
    <origin
      xyz="0 0 0"
      rpy="1.5707963267949 0 0" />
    <parent
      link="wrist_link" />
    <child
      link="roll_wrist_link" />
    <axis
      xyz="0 0 1" />
    <dynamics damping="0.7"/>
  </joint>

  <ros2_control name="GazeboSystem" type="system">

    <hardware>
      <plugin>gazebo_ros2_control/GazeboSystem</plugin>
    </hardware>

    <joint name="slide_base_joint">
      <command_interface name="position"/>
      <state_interface name="position">
        <param name="initial_value">0.0</param>
      </state_interface>
      <state_interface name="velocity"/>
    </joint>

    <joint name="body_joint">
      <command_interface name="position"/>
      <state_interface name="position">
        <param name="initial_value">0.0</param>
      </state_interface>
      <state_interface name="velocity"/>
    </joint>

    <joint name="shoulder_joint">
      <command_interface name="position"/>
      <state_interface name="position">
        <param name="initial_value">0.0</param>
      </state_interface>
      <state_interface name="velocity"/>
    </joint>

    <joint name="elbow_joint">
      <command_interface name="position"/>
      <state_interface name="position">
        <param name="initial_value">0.0</param>
      </state_interface>
      <state_interface name="velocity"/>
    </joint>

    <joint name="wrist_joint">
      <command_interface name="position"/>
      <state_interface name="position">
        <param name="initial_value">0.0</param>
      </state_interface>
      <state_interface name="velocity"/>
    </joint>

    <joint name="roll_wrist_joint">
      <command_interface name="position"/>
      <state_interface name="position">
        <param name="initial_value">0.0</param>
      </state_interface>
      <state_interface name="velocity"/>
    </joint>
  </ros2_control>

  <gazebo>
    <plugin name="gazebo_ros2_control" filename="libgazebo_ros2_control.so">
      <parameters>/home/juanmadrid/scorbot_ws/src/scorbot_er_v/config/scorbot_er_v_controllers.yaml</parameters>
    </plugin>
  </gazebo>
  
</robot>